Workbook

Sheet Premissas & Controle
B2: PAINEL DE PREMISSAS, CÂMBIO & ARQUITETURA (RAILWAY + CREWAI + DEEPSEEK FLASH V4)
B3: Altere as células amarelas para atualizar dinamicamente todas as projeções, conversores e cenários comparativos.
B5: 1. CONVERSORES DE MOEDA (USD, BRL & INR)
B6: Câmbio Dólar / Real (USD / BRL) | C6: 5.5 | D6: Cotação do Dólar em Reais (R$)
B7: Câmbio Dólar / Rúpia Indiana (USD / INR) | C7: 83.5 | D7: Cotação do Dólar em Rúpias Indianas (₹ INR)
B8: Inverso: Câmbio Real / Dólar (BRL / USD) | C8: =1/C6 | D8: Fórmula: 1 / (USD/BRL)
B9: Inverso: Câmbio Rúpia / Dólar (INR / USD) | C9: =1/C7 | D9: Fórmula: 1 / (USD/INR)
B10: Taxa de Impostos / Retenção Efetiva (Brasil) | C10: 0.08 | D10: Alíquota estimada Simples/Lucro Presumido para exportação
B12: 2. APPS MÓVEIS (SUÍTE 6 APPS E-LEARNING SAP)
B13: Razão P.A. de Usuários por App / Mês | C13: 500 | D13: Novos downloads mensais por app via Google Ads
B14: Razão P.A. de Assinantes Pagantes por App / Mês | C14: 5 | D14: Novos assinantes de $9/mês (1% de conversão)
B15: Preço Assinatura Mobile ($ USD) | C15: 9 | D15: Valor da assinatura mensal no Google Play
B16: Preço Equivalente em Rúpias Indianas (₹ INR) | C16: =C15*C7 | D16: Fórmula dinâmica: Preço USD * Câmbio USD/INR
B17: Comissão Google Play Store | C17: 0.15 | D17: Taxa Google Play até $1M anual
B18: Proporção Tráfego - Índia (%) | C18: 0.97 | D18: Percentual de usuários indianos
B19: Proporção Tráfego - EUA (%) | C19: 0.03 | D19: Percentual de usuários dos EUA
B20: eCPM Intersticial - Índia ($) | C20: 0.95 | D20: Valor por 1.000 exibições na Índia
B21: eCPM Intersticial - EUA ($) | C21: 10.5 | D21: Valor por 1.000 exibições nos EUA
B22: eCPM Banner - Índia ($) | C22: 0.12 | D22: Valor por 1.000 impressões na Índia
B23: eCPM Banner - EUA ($) | C23: 1.35 | D23: Valor por 1.000 impressões nos EUA
B24: CPI Médio Google Ads - Índia ($) | C24: 0.09 | D24: Custo por instalação na Índia
B25: CPI Médio Google Ads - EUA ($) | C25: 2.2 | D25: Custo por instalação nos EUA
B26: Impressões Intersticial / Usuário Free / Mês | C26: 56 | D26: 4 exibições a cada 90s em 14 sessões ativas
B27: Impressões Banner / Usuário Free / Mês | C27: 154 | D27: 11 exibições em 14 sessões ativas
B28: Custo IA DeepSeek Flash V4 por Usuário Mobile ($) | C28: 0.018 | D28: Perguntas de e-learning no DeepSeek Flash V4
B30: eCPM Intersticial Ponderado (Blended $) | C30: =C18*C20 + C19*C21 | D30: Fórmula: (% Índia * eCPM Índia) + (% EUA * eCPM EUA)
B31: eCPM Banner Ponderado (Blended $) | C31: =C18*C22 + C19*C23 | D31: Fórmula: (% Índia * Banner Índia) + (% EUA * Banner EUA)
B32: ARPU Mensal de Ads por Usuário Free ($) | C32: =(C26/1000)*C30 + (C27/1000)*C31 | D32: Receita mensal que cada usuário gratuito mobile gera em anúncios
B33: CPI Blended Google Ads ($) | C33: =C18*C24 + C19*C25 | D33: Custo médio ponderado por download mobile
B35: 3. COPILOT WINDOWS (PORTABLE, CREWAI NO RAILWAY & PLANO FREE)
B36: Preço Assinatura - Índia ($ USD) | C36: 7 | D36: Preço planejado para o mercado indiano
B37: Preço Assinatura Índia em Rúpias (₹ INR) | C37: =C36*C7 | D37: Fórmula dinâmica: $7 * Câmbio USD/INR (~₹584 INR)
B38: Preço Assinatura - Europa/EUA Pro ($ USD) | C38: 15 | D38: Plano profissional para consultores seniores
B39: Preço Assinatura - Europa/EUA Power ($ USD) | C39: 25 | D39: Plano power para alta intensidade de agentes
B40: Tíquete Médio Ponderado Ocidental ($ USD) | C40: 18.5 | D40: Mix 65% Pro ($15) e 35% Power ($25)
B41: Taxa Processamento Stripe/Paddle | C41: 0.04 | D41: Taxa de gateway de pagamento para software Windows
B42: Custo IA DeepSeek Flash V4 por Tarefa CrewAI ($) | C42: 0.0006 | D42: Pipeline multi-agente CrewAI (Análise + Sintaxe + Doc)
B43: Custo Mensal por Usuário Desktop Free ($) | C43: 0.035 | D43: Cota diária limitada no Plano Gratuito (DeepSeek Flash V4)
B44: Monetização / ARPU Mensal do Usuário Desktop Free ($) | C44: 0.08 | D44: Parcerias/Sponsored jobs/Ads discretos no Desktop Free
B45: Custo Base Railway Inicial (Containers CrewAI) | C45: 20 | D45: Plano de containers Docker no Railway
...

Sheet Calculadora 12 Meses
B2: SIMULADOR FINANCEIRO MÊS A MÊS - ECOSSISTEMA SAP AI (RAILWAY + CREWAI + DEEPSEEK FLASH V4)
B4: Métrica / Linha de Demonstração | C4: M1 | D4: M2 | E4: M3 | F4: M4 | G4: M5 | H4: M6 | I4: M7 | J4: M8 | K4: M9 | L4: M10 | M4: M11 | N4: M12 | O4: TOTAL ANO 1
B5: 1. BASE DE USUÁRIOS E CLIENTES (UNIDADES)
B6: Apps Móveis Ativos na Suíte | C6: 1 | D6: 3 | E6: 6 | F6: 6 | G6: 6 | H6: 6 | I6: 6 | J6: 6 | K6: 6 | L6: 6 | M6: 6 | N6: 6 | O6: 6
B7: Usuários Ativos Mobile Totais (MAU) | C7: =C6*'Premissas & Controle'!$C$13 | D7: =C7 + D6*'Premissas & Controle'!$C$13 | E7: =D7 + E6*'Premissas & Controle'!$C$13 | F7: =E7 + F6*'Premissas & Controle'!$C$13 | G7: =F7 + G6*'Premissas & Controle'!$C$13 | H7: =G7 + H6*'Premissas & Controle'!$C$13 | I7: =H7 + I6*'Premissas & Controle'!$C$13 | J7: =I7 + J6*'Premissas & Controle'!$C$13 | K7: =J7 + K6*'Premissas & Controle'!$C$13 | ... N7: =M7 + N6*'Premissas & Controle'!$C$13 | O7: =N7
B8: Assinantes Mobile Pagantes ($9/mês) | C8: =C6*'Premissas & Controle'!$C$14 | D8: =C8 + D6*'Premissas & Controle'!$C$14 | E8: =D8 + E6*'Premissas & Controle'!$C$14 | F8: =E8 + F6*'Premissas & Controle'!$C$14 | G8: =F8 + G6*'Premissas & Controle'!$C$14 | H8: =G8 + H6*'Premissas & Controle'!$C$14 | I8: =H8 + I6*'Premissas & Controle'!$C$14 | J8: =I8 + J6*'Premissas & Controle'!$C$14 | K8: =J8 + K6*'Premissas & Controle'!$C$14 | ... N8: =M8 + N6*'Premissas & Controle'!$C$14 | O8: =N8
B9: Usuários Ativos Copilot Desktop - PLANO FREE | C9: 150 | D9: 400 | E9: 800 | F9: 1400 | G9: 2200 | H9: 3200 | I9: 4200 | J9: 5200 | K9: 6100 | L9: 6800 | M9: 7400 | N9: 8000 | O9: =N9
B10: Assinantes Copilot Windows Desktop (Pagantes) | C10: 35 | D10: 80 | E10: 160 | F10: 260 | G10: 400 | H10: 600 | I10: 800 | J10: 1000 | K10: 1200 | L10: 1350 | M10: 1500 | N10: 1600 | O10: =N10
B11: Assinantes Extensão Chrome Light | C11: 5 | D11: 15 | E11: 30 | F11: 50 | G11: 80 | H11: 110 | I11: 140 | J11: 170 | K11: 195 | L11: 220 | M11: 235 | N11: 250 | O11: =N11
B12: 2. RECEITAS BRUTAS CONSOLIDADAS (USD $)
B13: Receita de Anúncios Mobile (AdMob) | C13: =(C7 - C8) * 'Premissas & Controle'!$C$32 | D13: =(D7 - D8) * 'Premissas & Controle'!$C$32 | E13: =(E7 - E8) * 'Premissas & Controle'!$C$32 | F13: =(F7 - F8) * 'Premissas & Controle'!$C$32 | G13: =(G7 - G8) * 'Premissas & Controle'!$C$32 | H13: =(H7 - H8) * 'Premissas & Controle'!$C$32 | I13: =(I7 - I8) * 'Premissas & Controle'!$C$32 | J13: =(J7 - J8) * 'Premissas & Controle'!$C$32 | ... N13: =(N7 - N8) * 'Premissas & Controle'!$C$32 | O13: =SUM(C13:N13)
B14: Receita Assinaturas Mobile Líquida (85%) | C14: =C8 * 'Premissas & Controle'!$C$15 * (1 - 'Premissas & Controle'!$C$17) | D14: =D8 * 'Premissas & Controle'!$C$15 * (1 - 'Premissas & Controle'!$C$17) | E14: =E8 * 'Premissas & Controle'!$C$15 * (1 - 'Premissas & Controle'!$C$17) | F14: =F8 * 'Premissas & Controle'!$C$15 * (1 - 'Premissas & Controle'!$C$17) | G14: =G8 * 'Premissas & Controle'!$C$15 * (1 - 'Premissas & Controle'!$C$17) | H14: =H8 * 'Premissas & Controle'!$C$15 * (1 - 'Premissas & Controle'!$C$17) | I14: =I8 * 'Premissas & Controle'!$C$15 * (1 - 'Premissas & Controle'!$C$17) | J14: =J8 * 'Premissas & Controle'!$C$15 * (1 - 'Premissas & Controle'!$C$17) | ... N14: =N8 * 'Premissas & Controle'!$C$15 * (1 - 'Premissas & Controle'!$C$17) | O14: =SUM(C14:N14)
B15: Receita Copilot Windows Desktop (Assinaturas) | C15: =C10 * (0.625*'Premissas & Controle'!$C$36 + 0.375*'Premissas & Controle'!$C$40) | D15: =D10 * (0.625*'Premissas & Controle'!$C$36 + 0.375*'Premissas & Controle'!$C$40) | E15: =E10 * (0.625*'Premissas & Controle'!$C$36 + 0.375*'Premissas & Controle'!$C$40) | F15: =F10 * (0.625*'Premissas & Controle'!$C$36 + 0.375*'Premissas & Controle'!$C$40) | G15: =G10 * (0.625*'Premissas & Controle'!$C$36 + 0.375*'Premissas & Controle'!$C$40) | H15: =H10 * (0.625*'Premissas & Controle'!$C$36 + 0.375*'Premissas & Controle'!$C$40) | I15: =I10 * (0.625*'Premissas & Controle'!$C$36 + 0.375*'Premissas & Controle'!$C$40) | J15: =J10 * (0.625*'Premissas & Controle'!$C$36 + 0.375*'Premissas & Controle'!$C$40) | ... N15: =N10 * (0.625*'Premissas & Controle'!$C$36 + 0.375*'Premissas & Controle'!$C$40) | O15: =SUM(C15:N15)
B16: Receita Copilot Desktop Free (Parcerias / Ads) | C16: =C9 * 'Premissas & Controle'!$C$44 | D16: =D9 * 'Premissas & Controle'!$C$44 | E16: =E9 * 'Premissas & Controle'!$C$44 | F16: =F9 * 'Premissas & Controle'!$C$44 | G16: =G9 * 'Premissas & Controle'!$C$44 | H16: =H9 * 'Premissas & Controle'!$C$44 | I16: =I9 * 'Premissas & Controle'!$C$44 | J16: =J9 * 'Premissas & Controle'!$C$44 | ... N16: =N9 * 'Premissas & Controle'!$C$44 | O16: =SUM(C16:N16)
B17: Receita Extensão Chrome (Ads + Assinaturas) | C17: =C11 * (0.60*'Premissas & Controle'!$C$48 + 0.40*'Premissas & Controle'!$C$50) + (C11*26)*'Premissas & Controle'!$C$51 | D17: =D11 * (0.60*'Premissas & Controle'!$C$48 + 0.40*'Premissas & Controle'!$C$50) + (D11*26)*'Premissas & Controle'!$C$51 | E17: =E11 * (0.60*'Premissas & Controle'!$C$48 + 0.40*'Premissas & Controle'!$C$50) + (E11*26)*'Premissas & Controle'!$C$51 | F17: =F11 * (0.60*'Premissas & Controle'!$C$48 + 0.40*'Premissas & Controle'!$C$50) + (F11*26)*'Premissas & Controle'!$C$51 | G17: =G11 * (0.60*'Premissas & Controle'!$C$48 + 0.40*'Premissas & Controle'!$C$50) + (G11*26)*'Premissas & Controle'!$C$51 | H17: =H11 * (0.60*'Premissas & Controle'!$C$48 + 0.40*'Premissas & Controle'!$C$50) + (H11*26)*'Premissas & Controle'!$C$51 | I17: =I11 * (0.60*'Premissas & Controle'!$C$48 + 0.40*'Premissas & Controle'!$C$50) + (I11*26)*'Premissas & Controle'!$C$51 | J17: =J11 * (0.60*'Premissas & Controle'!$C$48 + 0.40*'Premissas & Controle'!$C$50) + (J11*26)*'Premissas & Controle'!$C$51 | ... N17: =N11 * (0.60*'Premissas & Controle'!$C$48 + 0.40*'Premissas & Controle'!$C$50) + (N11*26)*'Premissas & Controle'!$C$51 | O17: =SUM(C17:N17)
B18: TOTAL RECEITA BRUTA/LÍQUIDA CONSOLIDADA ($) | C18: =SUM(C13:C17) | D18: =SUM(D13:D17) | E18: =SUM(E13:E17) | F18: =SUM(F13:F17) | G18: =SUM(G13:G17) | H18: =SUM(H13:H17) | I18: =SUM(I13:I17) | J18: =SUM(J13:J17) | ... O18: =SUM(O13:O17)
B19: 3. CUSTOS OPERACIONAIS (RAILWAY, CREWAI, DEEPSEEK FLASH V4 & MÍDIA)
B20: Mídia Google Ads Mobile (Instalações) | C20: =C6 * 'Premissas & Controle'!$C$13 * 'Premissas & Controle'!$C$33 | D20: =D6 * 'Premissas & Controle'!$C$13 * 'Premissas & Controle'!$C$33 | E20: =E6 * 'Premissas & Controle'!$C$13 * 'Premissas & Controle'!$C$33 | F20: =F6 * 'Premissas & Controle'!$C$13 * 'Premissas & Controle'!$C$33 | G20: =G6 * 'Premissas & Controle'!$C$13 * 'Premissas & Controle'!$C$33 | H20: =H6 * 'Premissas & Controle'!$C$13 * 'Premissas & Controle'!$C$33 | I20: =I6 * 'Premissas & Controle'!$C$13 * 'Premissas & Controle'!$C$33 | J20: =J6 * 'Premissas & Controle'!$C$13 * 'Premissas & Controle'!$C$33 | ... N20: =N6 * 'Premissas & Controle'!$C$13 * 'Premissas & Controle'!$C$33 | O20: =SUM(C20:N20)
B21: Mídia Comercial Desktop (LinkedIn + Search + Meta) | C21: 75 | D21: 200 | E21: 450 | F21: 700 | G21: 1000 | H21: 2100 | I21: 3000 | J21: 3700 | K21: 4300 | L21: 4700 | M21: 5000 | N21: 5500 | O21: =SUM(C21:N21)
B22: Custo IA DeepSeek Flash V4 (CrewAI Agentes + Mobile) | C22: =C7*'Premissas & Controle'!$C$28 + C10*700*'Premissas & Controle'!$C$42 + C9*'Premissas & Controle'!$C$43 | D22: =D7*'Premissas & Controle'!$C$28 + D10*700*'Premissas & Controle'!$C$42 + D9*'Premissas & Controle'!$C$43 | E22: =E7*'Premissas & Controle'!$C$28 + E10*700*'Premissas & Controle'!$C$42 + E9*'Premissas & Controle'!$C$43 | F22: =F7*'Premissas & Controle'!$C$28 + F10*700*'Premissas & Controle'!$C$42 + F9*'Premissas & Controle'!$C$43 | G22: =G7*'Premissas & Controle'!$C$28 + G10*700*'Premissas & Controle'!$C$42 + G9*'Premissas & Controle'!$C$43 | H22: =H7*'Premissas & Controle'!$C$28 + H10*700*'Premissas & Controle'!$C$42 + H9*'Premissas & Controle'!$C$43 | I22: =I7*'Premissas & Controle'!$C$28 + I10*700*'Premissas & Controle'!$C$42 + I9*'Premissas & Controle'!$C$43 | J22: =J7*'Premissas & Controle'!$C$28 + J10*700*'Premissas & Controle'!$C$42 + J9*'Premissas & Controle'!$C$43 | ... N22: =N7*'Premissas & Controle'!$C$28 + N10*700*'Premissas & Controle'!$C$42 + N9*'Premissas & Controle'!$C$43 | O22: =SUM(C22:N22)
B23: Backend Railway (Containers Docker CrewAI + APIs) | C23: 20 | D23: 30 | E23: 45 | F23: 60 | G23: 80 | H23: 105 | I23: 130 | J23: 155 | K23: 175 | L23: 195 | M23: 215 | N23: 230 | O23: =SUM(C23:N23)
B24: Taxas Gateways de Pagamento (Stripe/Paddle 4%) | C24: =(C15 + C17) * 'Premissas & Controle'!$C$41 | D24: =(D15 + D17) * 'Premissas & Controle'!$C$41 | E24: =(E15 + E17) * 'Premissas & Controle'!$C$41 | F24: =(F15 + F17) * 'Premissas & Controle'!$C$41 | G24: =(G15 + G17) * 'Premissas & Controle'!$C$41 | H24: =(H15 + H17) * 'Premissas & Controle'!$C$41 | I24: =(I15 + I17) * 'Premissas & Controle'!$C$41 | J24: =(J15 + J17) * 'Premissas & Controle'!$C$41 | ... N24: =(N15 + N17) * 'Premissas & Controle'!$C$41 | O24: =SUM(C24:N24)
B25: TOTAL CUSTOS OPERACIONAIS ($) | C25: =SUM(C20:C24) | D25: =SUM(D20:D24) | E25: =SUM(E20:E24) | F25: =SUM(F20:F24) | G25: =SUM(G20:G24) | H25: =SUM(H20:H24) | I25: =SUM(I20:I24) | J25: =SUM(J20:J24) | ... O25: =SUM(O20:O24)
B26: 4. DEMONSTRATIVO DE RESULTADOS & LUCRO LÍQUIDO
B27: LUCRO LÍQUIDO MENSAL (USD $) | C27: =C18 - C25 | D27: =D18 - D25 | E27: =E18 - E25 | F27: =F18 - F25 | G27: =G18 - G25 | H27: =H18 - H25 | I27: =I18 - I25 | J27: =J18 - J25 | ... O27: =O18 - O25
B28: Margem Líquida (%) | C28: =C27 / C18 | D28: =D27 / D18 | E28: =E27 / E18 | F28: =F27 / F18 | G28: =G27 / G18 | H28: =H27 / H18 | I28: =I27 / I18 | J28: =J27 / J18 | ... O28: =O27 / O18
B29: Lucro Líquido Acumulado (USD $) | C29: =C27 | D29: =C29 + D27 | E29: =D29 + E27 | F29: =E29 + F27 | G29: =F29 + G27 | H29: =G29 + H27 | I29: =H29 + I27 | J29: =I29 + J27 | K29: =J29 + K27 | ... N29: =M29 + N27 | O29: =N29
B30: 5. CONVERSÃO MULTI-MOEDA (REAIS BRL & RÚPIAS INDIANAS INR)
B31: LUCRO LÍQUIDO MENSAL EM REAIS (BRL - R$) | C31: =C27 * 'Premissas & Controle'!$C$6 | D31: =D27 * 'Premissas & Controle'!$C$6 | E31: =E27 * 'Premissas & Controle'!$C$6 | F31: =F27 * 'Premissas & Controle'!$C$6 | G31: =G27 * 'Premissas & Controle'!$C$6 | H31: =H27 * 'Premissas & Controle'!$C$6 | I31: =I27 * 'Premissas & Controle'!$C$6 | J31: =J27 * 'Premissas & Controle'!$C$6 | ... O31: =O27 * 'Premissas & Controle'!$C$6
B32: LUCRO LÍQUIDO ACUMULADO EM REAIS (BRL - R$) | C32: =C31 | D32: =C32 + D31 | E32: =D32 + E31 | F32: =E32 + F31 | G32: =F32 + G31 | H32: =G32 + H31 | I32: =H32 + I31 | J32: =I32 + J31 | K32: =J32 + K31 | ... N32: =M32 + N31 | O32: =N32
B33: LUCRO LÍQUIDO MENSAL EM RÚPIAS (INR - ₹) | C33: =C27 * 'Premissas & Controle'!$C$7 | D33: =D27 * 'Premissas & Controle'!$C$7 | E33: =E27 * 'Premissas & Controle'!$C$7 | F33: =F27 * 'Premissas & Controle'!$C$7 | G33: =G27 * 'Premissas & Controle'!$C$7 | H33: =H27 * 'Premissas & Controle'!$C$7 | I33: =I27 * 'Premissas & Controle'!$C$7 | J33: =J27 * 'Premissas & Controle'!$C$7 | ... O33: =O27 * 'Premissas & Controle'!$C$7

Sheet Comparativo de Cenários
B2: COMPARATIVO EXECUTIVO DE CENÁRIOS NO M12 (100% DINÂMICO)
B3: Todos os faturamentos e lucros recalculam dinamicamente a partir dos assinantes e parâmetros de Premissas.
B5: Indicador Estratégico no Mês 12 | C5: Cenário Conservador | D5: Cenário Realista (P50) | E5: Cenário Agressivo | F5: Fórmula / Lógica
B6: Assinantes Copilot Windows Pagantes (M12) | C6: 1200 | D6: 1600 | E6: 4500 | F6: Variável de escala de assinantes desktop
B7: Usuários Ativos Copilot Desktop - PLANO FREE (M12) | C7: 5000 | D7: 8000 | E7: 22000 | F7: Base gratuita gerando conversão e receita de ads
B8: Usuários Ativos Mobile MAU (M12) | C8: 10000 | D8: 12500 | E8: 31500 | F8: Base ativa da suíte de 6 apps móveis
B9: Assinantes Mobile Pagantes ($9/mês) (M12) | C9: 100 | D9: 125 | E9: 315 | F9: Assinantes mobile no Google Play
B10: Assinantes Extensão Chrome Light (M12) | C10: 180 | D10: 250 | E10: 750 | F10: Assinantes do assistente de código no Chrome
B11: Investimento Mídia Mensal no M12 ($ USD) | C11: 4200 | D11: 5960 | E11: 11375 | F11: Investimento em Google, LinkedIn e Meta Ads
B13: FATURAMENTO BRUTO MENSAL M12 (USD $) | C13: =C6*(0.625*'Premissas & Controle'!$C$36 + 0.375*'Premissas & Controle'!$C$40) + C7*'Premissas & Controle'!$C$44 + (C8-C9)*'Premissas & Controle'!$C$32 + C9*'Premissas & Controle'!$C$15*(1-'Premissas & Controle'!$C$17) + C10*(0.6*'Premissas & Controle'!$C$48 + 0.4*'Premissas & Controle'!$C$50) | D13: =D6*(0.625*'Premissas & Controle'!$C$36 + 0.375*'Premissas & Controle'!$C$40) + D7*'Premissas & Controle'!$C$44 + (D8-D9)*'Premissas & Controle'!$C$32 + D9*'Premissas & Controle'!$C$15*(1-'Premissas & Controle'!$C$17) + D10*(0.6*'Premissas & Controle'!$C$48 + 0.4*'Premissas & Controle'!$C$50) | E13: =E6*(0.625*'Premissas & Controle'!$C$36 + 0.375*'Premissas & Controle'!$C$40) + E7*'Premissas & Controle'!$C$44 + (E8-E9)*'Premissas & Controle'!$C$32 + E9*'Premissas & Controle'!$C$15*(1-'Premissas & Controle'!$C$17) + E10*(0.6*'Premissas & Controle'!$C$48 + 0.4*'Premissas & Controle'!$C$50) | F13: Fórmula dinâmica considerando receita de todos os produtos e planos
B14: FATURAMENTO MENSAL M12 EM REAIS (BRL - R$) | C14: =C13 * 'Premissas & Controle'!$C$6 | D14: =D13 * 'Premissas & Controle'!$C$6 | E14: =E13 * 'Premissas & Controle'!$C$6 | F14: Fórmula: Faturamento USD * Câmbio USD/BRL
B15: FATURAMENTO MENSAL M12 EM RÚPIAS (INR - ₹) | C15: =C13 * 'Premissas & Controle'!$C$7 | D15: =D13 * 'Premissas & Controle'!$C$7 | E15: =E13 * 'Premissas & Controle'!$C$7 | F15: Fórmula: Faturamento USD * Câmbio USD/INR
B16: Custos Totais no Mês 12 ($ USD) | C16: =C11 + (C8*'Premissas & Controle'!$C$28 + C6*700*'Premissas & Controle'!$C$42 + C7*'Premissas & Controle'!$C$43) + 180 + C13*0.035 | D16: =D11 + (D8*'Premissas & Controle'!$C$28 + D6*700*'Premissas & Controle'!$C$42 + D7*'Premissas & Controle'!$C$43) + 230 + D13*0.035 | E16: =E11 + (E8*'Premissas & Controle'!$C$28 + E6*700*'Premissas & Controle'!$C$42 + E7*'Premissas & Controle'!$C$43) + 450 + E13*0.035 | F16: Fórmula: Mídia + IA DeepSeek Flash V4 + Railway Containers + Gateways
B17: LUCRO LÍQUIDO MENSAL NO MÊS 12 (USD $) | C17: =C13 - C16 | D17: =D13 - D16 | E17: =E13 - E16 | F17: Fórmula: Faturamento Bruto - Custos Totais
B18: LUCRO LÍQUIDO MENSAL NO M12 (BRL - R$) | C18: =C17 * 'Premissas & Controle'!$C$6 | D18: =D17 * 'Premissas & Controle'!$C$6 | E18: =E17 * 'Premissas & Controle'!$C$6 | F18: Fórmula: Lucro USD * Câmbio USD/BRL
B19: LUCRO LÍQUIDO MENSAL NO M12 (INR - ₹) | C19: =C17 * 'Premissas & Controle'!$C$7 | D19: =D17 * 'Premissas & Controle'!$C$7 | E19: =E17 * 'Premissas & Controle'!$C$7 | F19: Fórmula: Lucro USD * Câmbio USD/INR
B20: Margem Líquida no Mês 12 (%) | C20: =C17 / C13 | D20: =D17 / D13 | E20: =E17 / E13 | F20: Fórmula: Lucro Líquido / Faturamento Bruto
B21: LUCRO LÍQUIDO ESTIMADO ACUMULADO ANO 1 (BRL) | C21: =C18 * 5.2 | D21: ='Calculadora 12 Meses'!O32 | E21: =E18 * 5.4 | F21: Fórmula dinâmica: Multiplicador da curva de ramp-up
